Workbook

Sheet Instrukcja
B2: WNIOSEK O UBEZPIECZENIE MAJĄTKOWE
B3: Aura Expert — szablon do wypełnienia w arkuszu kalkulacyjnym
B5: JAK WYPEŁNIĆ
B6: Kolejność | C6: Wypełniaj zakładki po kolei — od „1. Dane firmy” do „8. Podsumowanie”.
B7: Pola wymagane | C7: Oznaczone gwiazdką * i wyróżnione kremowym tłem. Bez nich wniosek nie zostanie rozpatrzony.
B8: Listy rozwijane | C8: Komórki ze strzałką po prawej — wybierz wartość z listy zamiast wpisywać własną.
B9: Pola TAK / NIE | C9: Odpowiednik pól wyboru z formularza internetowego. Domyślnie „NIE”.
B10: Kwoty | C10: Podawaj wartość odtworzeniową (koszt zakupu nowego), w pełnych złotych, bez groszy.
B11: Sumy | C11: Pola szare liczą się same — nie nadpisuj ich.
B12: Lokalizacje | C12: Szablon obejmuje 3 lokalizacje. Wypełnij tylko te faktycznie użytkowane; przy większej liczbie skontaktuj się z agentem.
B13: Kontrola spójności | C13: Na dole każdej zakładki lokalizacji sprawdzane jest, czy sumy zgadzają się z wykazem sprzętu. Czerwone podświetlenie oznacza rozbieżność do poprawienia.
B14: Ochrona arkusza | C14: Zablokowane są wyłącznie etykiety i formuły — żeby ich przypadkiem nie skasować. Ochrona jest bez hasła i można ją zdjąć: Recenzja → Nie chroń arkusza.
B16: ZAWARTOŚĆ SKOROSZYTU
B17: 1. Dane firmy | C17: Sekcja 1 — dane ubezpieczającego · Sekcja 3 — profil działalności
B18: 2–4. Lokalizacja 1–3 | C18: Sekcja 2 — charakterystyka obiektu · Sekcja 4A — ppoż. · Sekcja 4B — antykradzieżowe · sumy ubezpieczenia
B19: 5. Sprzęt medyczny | C19: Wykaz urządzeń medycznych i estetycznych, z przypisaniem do lokalizacji
B20: 6. Elektronika EEI | C20: Wykaz sprzętu IT, kas fiskalnych i terminali, z przypisaniem do lokalizacji
B21: 7. Szkodowość | C21: Sekcja 7 — szkody z ostatnich 5 lat
B22: 8. Podsumowanie | C22: Sekcja 5 — zakres · Sekcja 6 — łączna suma · Sekcja 8 — obecna polisa · Sekcja 9 — uwagi i oświadczenia
B24: PO WYPEŁNIENIU
B25: Odeślij wypełniony plik do swojego agenta Aura Expert. Ten sam wniosek można złożyć online — wtedy sumy i wykaz sprzętu przepiszą się do systemu automatycznie.

Sheet 1. Dane firmy
B2: WNIOSEK O UBEZPIECZENIE MAJĄTKOWE
B3: Krok 1 z 8 — dane ubezpieczającego i profil działalności. Pola oznaczone * są wymagane.
B5: SEKCJA 1 — DANE UBEZPIECZAJĄCEGO / UBEZPIECZONEGO
B6: Nazwa firmy / imię i nazwisko * | D6: np. Beauty Studio sp. z o.o.
B7: NIP | D7: 000-000-00-00
B8: REGON
B9: KRS
B10: Forma prawna
B11: Adres siedziby * | D11: ul. Przykładowa 1, 00-000 Warszawa
B12: Numer PKD | D12: np. 96.02.Z
B13: E-mail kontaktowy * | D13: biuro@firma.pl
B14: Telefon * | D14: +48 000 000 000
B15: Osoba do kontaktu
B16: Stanowisko
B18: SEKCJA 3 — PROFIL DZIAŁALNOŚCI
B19: Rodzaj działalności * | D19: np. Salon kosmetyczny, klinika estetyczna
B20: Liczba pracowników
B21: Szacunkowy roczny obrót
B23: Sekcje 2 i 4 (charakterystyka obiektu oraz zabezpieczenia) znajdują się na zakładkach „Lokalizacja 1–3”.

Sheet 2. Lokalizacja 1
B2: LOKALIZACJA 1
B3: Lokalizacja 1 z 3 — wypełnij tylko dla faktycznie użytkowanych lokalizacji.
B5: SEKCJA 2 — LOKALIZACJA I CHARAKTERYSTYKA BUDYNKU / LOKALU
B6: Nazwa lokalizacji | D6: np. Oddział Centrum
B7: Adres lokalizacji ubezpieczenia * | D7: jeśli różny od siedziby
B8: Typ lokalu
B9: Piętro / kondygnacja | D9: np. 0, 1, -1
B10: Powierzchnia (m²) | D10: np. 120
B11: Rok budowy | D11: np. 1995
B12: Rok ostatniego remontu | D12: np. 2020
B13: Materiał ścian
B14: Pokrycie dachu
B15: Stan techniczny
B16: Ogrzewanie
B17: Budynek własny (nie najemca) | C17: NIE
B18: Materiały palne w produkcji / procesie | C18: NIE
B20: SEKCJA 4A — ZABEZPIECZENIA PRZECIWPOŻAROWE
B21: Gaśnice (liczba sztuk) | D21: np. 2
B22: Data przeglądu gaśnic | D22: dd.mm.rrrr
B23: Odległość od PSP (km) | D23: np. 3
B24: Hydranty wewnętrzne | C24: NIE
B25: System alarmowania pożaru (SAP) | C25: NIE
B26: Tryskacze / automatyczny system gaśniczy | C26: NIE
B27: Oznakowane drogi ewakuacyjne | C27: NIE
B28: Zakaz palenia na obiekcie | C28: NIE
B30: SEKCJA 4B — ZABEZPIECZENIA ANTYKRADZIEŻOWE
B31: Alarm — typ | C31: brak
B32: Agencja ochrony (nazwa) | D32: np. Securitas, G4S
B33: Sejf / szafa stalowa — klasa | C33: brak
B34: Ogrodzenie terenu | C34: NIE
B35: Agencja ochrony czynna 24h | C35: NIE
B36: Monitoring wizyjny (CCTV) | C36: NIE
B37: Kraty w oknach | C37: NIE
B38: Rolety antywłamaniowe | C38: NIE
B39: Zamki atestowane | C39: NIE
B40: Drzwi atestowane (antywłamaniowe) | C40: NIE
B41: Szyby antywłamaniowe | C41: NIE
B42: Komputerowy system alarmowy | C42: NIE
B44: SUMY UBEZPIECZENIA DLA TEJ LOKALIZACJI (PLN)
B45: Wpisz szacunkową wartość odtworzeniową (koszt zakupu nowego) każdej pozycji.
...

Sheet 3. Lokalizacja 2
B2: LOKALIZACJA 2
B3: Lokalizacja 2 z 3 — wypełnij tylko dla faktycznie użytkowanych lokalizacji.
B5: SEKCJA 2 — LOKALIZACJA I CHARAKTERYSTYKA BUDYNKU / LOKALU
B6: Nazwa lokalizacji | D6: np. Oddział Centrum
B7: Adres lokalizacji ubezpieczenia | D7: jeśli różny od siedziby
B8: Typ lokalu
B9: Piętro / kondygnacja | D9: np. 0, 1, -1
B10: Powierzchnia (m²) | D10: np. 120
B11: Rok budowy | D11: np. 1995
B12: Rok ostatniego remontu | D12: np. 2020
B13: Materiał ścian
B14: Pokrycie dachu
B15: Stan techniczny
B16: Ogrzewanie
B17: Budynek własny (nie najemca) | C17: NIE
B18: Materiały palne w produkcji / procesie | C18: NIE
B20: SEKCJA 4A — ZABEZPIECZENIA PRZECIWPOŻAROWE
B21: Gaśnice (liczba sztuk) | D21: np. 2
B22: Data przeglądu gaśnic | D22: dd.mm.rrrr
B23: Odległość od PSP (km) | D23: np. 3
B24: Hydranty wewnętrzne | C24: NIE
B25: System alarmowania pożaru (SAP) | C25: NIE
B26: Tryskacze / automatyczny system gaśniczy | C26: NIE
B27: Oznakowane drogi ewakuacyjne | C27: NIE
B28: Zakaz palenia na obiekcie | C28: NIE
B30: SEKCJA 4B — ZABEZPIECZENIA ANTYKRADZIEŻOWE
B31: Alarm — typ | C31: brak
B32: Agencja ochrony (nazwa) | D32: np. Securitas, G4S
B33: Sejf / szafa stalowa — klasa | C33: brak
B34: Ogrodzenie terenu | C34: NIE
B35: Agencja ochrony czynna 24h | C35: NIE
B36: Monitoring wizyjny (CCTV) | C36: NIE
B37: Kraty w oknach | C37: NIE
B38: Rolety antywłamaniowe | C38: NIE
B39: Zamki atestowane | C39: NIE
B40: Drzwi atestowane (antywłamaniowe) | C40: NIE
B41: Szyby antywłamaniowe | C41: NIE
B42: Komputerowy system alarmowy | C42: NIE
B44: SUMY UBEZPIECZENIA DLA TEJ LOKALIZACJI (PLN)
B45: Wpisz szacunkową wartość odtworzeniową (koszt zakupu nowego) każdej pozycji.
...

Sheet 4. Lokalizacja 3
B2: LOKALIZACJA 3
B3: Lokalizacja 3 z 3 — wypełnij tylko dla faktycznie użytkowanych lokalizacji.
B5: SEKCJA 2 — LOKALIZACJA I CHARAKTERYSTYKA BUDYNKU / LOKALU
B6: Nazwa lokalizacji | D6: np. Oddział Centrum
B7: Adres lokalizacji ubezpieczenia | D7: jeśli różny od siedziby
B8: Typ lokalu
B9: Piętro / kondygnacja | D9: np. 0, 1, -1
B10: Powierzchnia (m²) | D10: np. 120
B11: Rok budowy | D11: np. 1995
B12: Rok ostatniego remontu | D12: np. 2020
B13: Materiał ścian
B14: Pokrycie dachu
B15: Stan techniczny
B16: Ogrzewanie
B17: Budynek własny (nie najemca) | C17: NIE
B18: Materiały palne w produkcji / procesie | C18: NIE
B20: SEKCJA 4A — ZABEZPIECZENIA PRZECIWPOŻAROWE
B21: Gaśnice (liczba sztuk) | D21: np. 2
B22: Data przeglądu gaśnic | D22: dd.mm.rrrr
B23: Odległość od PSP (km) | D23: np. 3
B24: Hydranty wewnętrzne | C24: NIE
B25: System alarmowania pożaru (SAP) | C25: NIE
B26: Tryskacze / automatyczny system gaśniczy | C26: NIE
B27: Oznakowane drogi ewakuacyjne | C27: NIE
B28: Zakaz palenia na obiekcie | C28: NIE
B30: SEKCJA 4B — ZABEZPIECZENIA ANTYKRADZIEŻOWE
B31: Alarm — typ | C31: brak
B32: Agencja ochrony (nazwa) | D32: np. Securitas, G4S
B33: Sejf / szafa stalowa — klasa | C33: brak
B34: Ogrodzenie terenu | C34: NIE
B35: Agencja ochrony czynna 24h | C35: NIE
B36: Monitoring wizyjny (CCTV) | C36: NIE
B37: Kraty w oknach | C37: NIE
B38: Rolety antywłamaniowe | C38: NIE
B39: Zamki atestowane | C39: NIE
B40: Drzwi atestowane (antywłamaniowe) | C40: NIE
B41: Szyby antywłamaniowe | C41: NIE
B42: Komputerowy system alarmowy | C42: NIE
B44: SUMY UBEZPIECZENIA DLA TEJ LOKALIZACJI (PLN)
B45: Wpisz szacunkową wartość odtworzeniową (koszt zakupu nowego) każdej pozycji.
...

Sheet 5. Sprzęt medyczny
B2: WNIOSEK O UBEZPIECZENIE MAJĄTKOWE
B3: Sprzęt medyczny i estetyczny — wykaz urządzeń we wszystkich lokalizacjach.
B5: Wskaż lokalizację dla każdego urządzenia. Suma wartości musi zgadzać się z pozycją „Sprzęt medyczny / estetyczny” w sumach danej lokalizacji.
B7: Lp. | C7: Lokalizacja | D7: Nazwa urządzenia | E7: Producent | F7: Model | G7: Nr seryjny | H7: Rok zakupu | I7: Wartość (PLN) | J7: Cert. CE | K7: Uwagi
B8: 1
B9: 2
B10: 3
B11: 4
B12: 5
B13: 6
B14: 7
B15: 8
B16: 9
B17: 10
B18: RAZEM | I18: =SUM(I8:I17) -> 0

Sheet 6. Elektronika EEI
B2: WNIOSEK O UBEZPIECZENIE MAJĄTKOWE
B3: Sprzęt elektroniczny (EEI) — komputery, kasy fiskalne, terminale, IT.
B5: Wskaż lokalizację dla każdego urządzenia. Suma wartości musi zgadzać się z pozycją „Sprzęt elektroniczny (IT, kasy fiskalne)” w sumach danej lokalizacji.
B7: Lp. | C7: Lokalizacja | D7: Nazwa urządzenia | E7: Producent | F7: Model | G7: Rok zakupu | H7: Wartość (PLN) | I7: Nr seryjny | J7: Uwagi
B8: 1
B9: 2
B10: 3
B11: 4
B12: 5
B13: 6
B14: 7
B15: 8
B16: 9
B17: 10
B18: RAZEM | H18: =SUM(H8:H17) -> 0

Sheet 7. Szkodowość
B2: WNIOSEK O UBEZPIECZENIE MAJĄTKOWE
B3: Sekcja 7 — historia szkodowości z ostatnich 5 lat.
B5: SEKCJA 7 — HISTORIA SZKODOWOŚCI (OSTATNIE 5 LAT)
B6: Brak szkód w ostatnich 5 latach | C6: TAK | D6: jeśli NIE — wypełnij tabelę poniżej
B8: Lp. | C8: Data szkody | D8: Przyczyna | E8: Kwota szkody (PLN) | F8: Odszkodowanie (PLN) | G8: Ubezpieczyciel
B9: 1
B10: 2
B11: 3
B12: 4
B13: 5
B14: RAZEM | E14: =SUM(E9:E13) -> 0 | F14: =SUM(F9:F13) -> 0

Sheet 8. Podsumowanie
B2: WNIOSEK O UBEZPIECZENIE MAJĄTKOWE
B3: Zakres, łączna suma ubezpieczenia, dotychczasowa polisa i oświadczenia.
B5: SEKCJA 5 — ZAKRES UBEZPIECZENIA (zaznacz potrzebne)
B6: Mienie od ognia i zdarzeń losowych | C6: NIE
B7: ↳ Szyby i inne przedmioty od stłuczenia | C7: NIE | D7: składowa „Mienie od ognia”
B8: ↳ Dewastacja / wandalizm | C8: NIE | D8: składowa „Mienie od ognia”
B9: ↳ Przepięcia elektryczne | C9: NIE | D9: składowa „Mienie od ognia”
B10: Kradzież z włamaniem i rabunek | C10: NIE
B11: Sprzęt elektroniczny (EEI) | C11: NIE
B12: Sprzęt medyczny / aparatura | C12: NIE
B14: SEKCJA 6 — ŁĄCZNA SUMA UBEZPIECZENIA (WSZYSTKIE LOKALIZACJE)
B15: Kategoria | C15: Lokalizacja 1 | D15: Lokalizacja 2 | E15: Lokalizacja 3 | F15: RAZEM
B16: Budynek / nakłady adaptacyjne (najemcy) | C16: ='2. Lokalizacja 1'!C46 -> 0 | D16: ='3. Lokalizacja 2'!C46 -> 0 | E16: ='4. Lokalizacja 3'!C46 -> 0 | F16: =SUM(C16:E16) -> 0
B17: Wyposażenie stałe (meble, zabudowa) | C17: ='2. Lokalizacja 1'!C47 -> 0 | D17: ='3. Lokalizacja 2'!C47 -> 0 | E17: ='4. Lokalizacja 3'!C47 -> 0 | F17: =SUM(C17:E17) -> 0
B18: Maszyny i urządzenia produkcyjne | C18: ='2. Lokalizacja 1'!C48 -> 0 | D18: ='3. Lokalizacja 2'!C48 -> 0 | E18: ='4. Lokalizacja 3'!C48 -> 0 | F18: =SUM(C18:E18) -> 0
B19: Środki obrotowe (towary, kosmetyki, preparaty) | C19: ='2. Lokalizacja 1'!C49 -> 0 | D19: ='3. Lokalizacja 2'!C49 -> 0 | E19: ='4. Lokalizacja 3'!C49 -> 0 | F19: =SUM(C19:E19) -> 0
B20: Sprzęt elektroniczny (IT, kasy fiskalne) | C20: ='2. Lokalizacja 1'!C50 -> 0 | D20: ='3. Lokalizacja 2'!C50 -> 0 | E20: ='4. Lokalizacja 3'!C50 -> 0 | F20: =SUM(C20:E20) -> 0
B21: Sprzęt medyczny / estetyczny | C21: ='2. Lokalizacja 1'!C51 -> 0 | D21: ='3. Lokalizacja 2'!C51 -> 0 | E21: ='4. Lokalizacja 3'!C51 -> 0 | F21: =SUM(C21:E21) -> 0
B22: Gotówka w lokalu (max jednorazowo) | C22: ='2. Lokalizacja 1'!C52 -> 0 | D22: ='3. Lokalizacja 2'!C52 -> 0 | E22: ='4. Lokalizacja 3'!C52 -> 0 | F22: =SUM(C22:E22) -> 0
B23: Gotówka w transporcie (max jednorazowo) | C23: ='2. Lokalizacja 1'!C53 -> 0 | D23: ='3. Lokalizacja 2'!C53 -> 0 | E23: ='4. Lokalizacja 3'!C53 -> 0 | F23: =SUM(C23:E23) -> 0
B24: Szyby i inne przedmioty od stłuczenia | C24: ='2. Lokalizacja 1'!C54 -> 0 | D24: ='3. Lokalizacja 2'!C54 -> 0 | E24: ='4. Lokalizacja 3'!C54 -> 0 | F24: =SUM(C24:E24) -> 0
B25: Mienie pracowników | C25: ='2. Lokalizacja 1'!C55 -> 0 | D25: ='3. Lokalizacja 2'!C55 -> 0 | E25: ='4. Lokalizacja 3'!C55 -> 0 | F25: =SUM(C25:E25) -> 0
B26: ŁĄCZNA SUMA UBEZPIECZENIA | C26: =SUM(C16:C25) -> 0 | D26: =SUM(D16:D25) -> 0 | E26: =SUM(E16:E25) -> 0 | F26: =SUM(F16:F25) -> 0
B28: SEKCJA 8 — DOTYCHCZASOWE UBEZPIECZENIE MIENIA
B29: Posiada aktualną polisę na mienie | C29: NIE
B30: Towarzystwo ubezpieczeń | D30: np. PZU, Allianz, Warta
B31: Numer polisy
B32: Ważność polisy do | D32: dd.mm.rrrr
B33: Roczna składka (PLN)
B35: SEKCJA 9 — UWAGI ORAZ OŚWIADCZENIA
B36: Uwagi, opis działalności, pytania do agenta
B43: Oświadczam, że wszystkie informacje podane w niniejszym wniosku są zgodne z prawdą i odzwierciedlają rzeczywisty stan faktyczny.
B46: Wyrażam zgodę na przetwarzanie moich danych osobowych przez Aura Expert sp. z o.o. w celu przygotowania oferty ubezpieczenia, zgodnie z RODO.
B50: Miejscowość i data *
B51: Imię, nazwisko i podpis osoby uprawnionej *

Sheet _listy
A1: forma_prawna | B1: pracownicy | C1: obrot | D1: typ_lokalu | E1: material_scian | F1: pokrycie_dachu | G1: stan_techniczny | H1: ogrzewanie | I1: alarm_typ | J1: sejf_klasa | K1: lokalizacje
A2: Jednoosobowa działalność gospodarcza | B2: 1 | C2: do 200 tys. PLN | D2: Lokal usługowy | E2: Cegła / mur | F2: Papa / asfalt | G2: Bardzo dobry | H2: Centralne (sieciowe) | I2: brak | J2: brak | K2: Lokalizacja 1
A3: Spółka cywilna | B3: 2–5 | C3: 200–500 tys. PLN | D3: Budynek wolnostojący | E3: Żelbet / beton | F3: Dachówka ceramiczna | G3: Dobry | H3: Gazowe | I3: Lokalny (sygnał dźwiękowy) | J3: I | K3: Lokalizacja 2
A4: Spółka z o.o. | B4: 6–10 | C4: 500 tys. – 1 mln PLN | D4: Lokal w centrum handlowym | E4: Drewno / szkielet drewniany | F4: Blacha trapezowa / panele | G4: Dostateczny | H4: Elektryczne | I4: Monitoring przez stację (SMS) | J4: II | K4: Lokalizacja 3
A5: Spółka akcyjna | B5: 11–25 | C5: 1–3 mln PLN | D5: Dom jednorodzinny | E5: Gazobeton / bloczki | F5: Strop żelbetowy (flat) | G5: Wymaga remontu | H5: Olejowe | I5: Monitoring przez agencję ochrony | J5: III
A6: Spółka jawna | B6: 26–50 | C6: powyżej 3 mln PLN | D6: Inny | E6: Inne | F6: Inne | H6: Pompą ciepła | J6: IV+
A7: Spółka komandytowa | B7: 51+ | H7: Inne
A8: Inne
